<robot name="pendulum">

    <joint name="pendulum_joint" type="continuous">
      <origin xyz="0.18 0 0.0" rpy="3.14159625 0 0"/>
      <axis xyz="-1 0 0"/>
      <parent link="world"/>
      <child link="pendulum_link"/>
      <dynamics damping="0.01"/>
      <limit effort="0" velocity="0"/>
      <safety_controller k_velocity="0"/>
    </joint>

    <link name="world">
      <inertial>
        <mass value="0" />
        <origin xyz="0.0 0.0 0" rpy="0 0 0" />
        <inertia  ixx="0" ixy="0" ixz="0"
                  iyy="0" iyz="0"
                  izz="0" />
      </inertial>
    </link>

    <link name="pendulum_link">
      <inertial>
        <mass value="0.05" />
        <origin xyz="0.0 0.0 0.25" rpy="0 0 0" />
        <inertia  ixx="0.001" ixy="0.0" ixz="0.0"
                  iyy="0.001" iyz="0.0"
                  izz="0.001" />
      </inertial>
      <visual>
        <origin xyz="0 0 0.25" rpy="0 0 0" />
        <geometry>
          <sphere radius="0.03"/>
        </geometry>
        <material name="Red" />
      </visual>
      <collision>
        <origin xyz="0 0 0.25" rpy="0 0 0" />
        <geometry>
          <sphere radius="0.03"/>
        </geometry>
      </collision>
    </link>
    
    <joint name="pendulum_fixed_joint" type="fixed">
      <origin xyz="0 0 0" rpy="0 0 0" />
      <parent link="pendulum_link"/>
      <child link="pendulum_rod_link"/>
    </joint>

    <link name="pendulum_rod_link">
      <inertial>
        <mass value="0.001" />
        <origin xyz="0 0 0" rpy="0 0 0" />
        <inertia  ixx="0.001" ixy="0.0" ixz="0.0"
                  iyy="0.001" iyz="0.0"
                  izz="0.001" />
      </inertial>
      <visual>
        <origin xyz="0 0 0.125" rpy="0 0 0" />
        <geometry>
          <cylinder radius="0.01" length="0.25"/>
        </geometry>
        <material name="Red" />
      </visual>
      <collision>
        <origin xyz="0 0 0.125" rpy="0 0 0" />
        <geometry>
          <cylinder radius="0.01" length="0.25"/>
        </geometry>
      </collision>
    </link>
</robot>
