<?xml version="1.0" ?>
<sdf version='1.5'>
  <model name='ur10'>
    <link name='base_link'>
<!--      <pose>0 0 0 0 0 0</pose>  -->
      <inertial>
        <pose>0 0 0 0 0 0</pose>
        <mass>4</mass>
        <inertia>
          <ixx>0.00610633</ixx>
          <ixy>0</ixy>
          <ixz>0</ixz>
          <iyy>0.00610633</iyy>
          <iyz>0</iyz>
          <izz>0.01125</izz>
        </inertia>
      </inertial>
      <collision name='base_link_collision'>
        <pose>0 0 0 0 0 0</pose>
        <geometry>
          <mesh>
            <uri>meshes/Base.obj</uri>
          </mesh>
        </geometry>
      </collision>
      <visual name='base_link_visual'>
        <pose>0 0 0 0 0 0</pose>
        <geometry>
          <mesh>
            <uri>meshes/Base.obj</uri>
          </mesh>
        </geometry>
      </visual>
    </link>
    <joint name='world_joint' type='revolute'>
      <parent>world</parent>
      <child>base_link</child>
      <axis>
        <limit>
          <lower>0</lower>
          <upper>0</upper>
        </limit>
        <use_parent_model_frame>1</use_parent_model_frame>
        <xyz>0 0 1</xyz>
      </axis>
    </joint>
    <link name='shoulder_link'>
      <pose>0 0 0.1273 0 0 0</pose>
      <inertial>
        <pose>0 0 0 0 0 0</pose>
        <mass>7.778</mass>
        <inertia>
          <ixx>0.0314743</ixx>
          <ixy>0</ixy>
          <ixz>0</ixz>
          <iyy>0.0314743</iyy>
          <iyz>0</iyz>
          <izz>0.0218756</izz>
        </inertia>
      </inertial>
      <collision name='shoulder_link_collision'>
        <pose>0 0 0 0 0 0</pose>
        <geometry>
          <mesh>
            <uri>meshes/Shoulder.obj</uri>
          </mesh>
        </geometry>
      </collision>
      <visual name='shoulder_link_visual'>
        <pose>0 0 0 0 0 0</pose>
        <geometry>
          <mesh>
            <uri>meshes/Shoulder.obj</uri>
          </mesh>
        </geometry>
      </visual>
    </link>
    <link name='base_shoulder_gear'>
      <pose>0 0 0.2273 0 0 0</pose>
      <inertial>
        <pose>0 0 0 0 0 0</pose>
        <mass>2.778</mass>
        <inertia>
          <ixx>1</ixx>
          <ixy>0</ixy>
          <ixz>0</ixz>
          <iyy>1</iyy>
          <iyz>0</iyz>
          <izz>1</izz>
        </inertia>
      </inertial>
      <visual name='base_shoulder_gear_visual'>
        <pose>0 0 0 0 0 0</pose>
        <geometry>
          <box>
            <size>0.025 0.025 0.025</size>
          </box>
        </geometry>
      </visual>
    </link>
  <!-- 
  <joint name='world_base_gear_joint' type='revolute'>
      <child>base_shoulder_gear</child>
      <parent>world</parent>
      <axis>
        <xyz>0 0 1</xyz>
        <limit>
           <upper>0</upper>
           <lower>0</lower>
        </limit>
      </axis>
    </joint>
-->
    <joint name='base_gear_joint' type='revolute'>
      <parent>base_link</parent>
      <child>base_shoulder_gear</child>
      <axis>
        <xyz>0 0 1</xyz>
        <use_parent_model_frame>1</use_parent_model_frame>
<!--   
        <xyz>0 0 1</xyz>
-->
      </axis>
    </joint>
    <joint name='shoulder_gear_joint' type='revolute'>
      <parent>base_shoulder_gear</parent>
      <child>shoulder_link</child>
      <axis>
        <xyz>0 0 1</xyz>
        <use_parent_model_frame>1</use_parent_model_frame>
<!--   
        <xyz>0 0 1</xyz>
-->
      </axis>
    </joint>
    <joint name='shoulder_pan_joint' type='gearbox'>
      <parent>base_link</parent>
      <child>shoulder_link</child>
      <gearbox_ratio>1.5</gearbox_ratio>
      <gearbox_reference_body>base_shoulder_gear</gearbox_reference_body>
      <axis>
         <xyz>0.0 0.0 -1.0</xyz>
        <limit>
          <lower>-6.28319</lower>
          <upper>6.28319</upper>
          <effort>330</effort>
          <velocity>2.16</velocity>
        </limit>
        <use_parent_model_frame>0</use_parent_model_frame>
      </axis>
      <axis2>
         <xyz>0.0 0.0 1.0</xyz>
        <use_parent_model_frame>0</use_parent_model_frame>
      </axis2>
    </joint>
   <!--
    <joint name='shoulder_pan_joint' type='revolute'>
      <child>shoulder_link</child>
      <parent>base_link</parent>
      <axis>
        <xyz>0 0 1</xyz>
        <limit>
          <lower>-6.28319</lower>
          <upper>6.28319</upper>
          <effort>330</effort>
          <velocity>2.16</velocity>
        </limit>
        <use_parent_model_frame>1</use_parent_model_frame>
      </axis>
    </joint>
-->
    <link name='upper_arm_link'>
      <pose>0 0.220941 0.1273 3.14159 1.57079 3.14159</pose>
      <inertial>
        <pose>0 0 0.306 0 0 0</pose>
        <mass>12.93</mass>
        <inertia>
          <ixx>0.421754</ixx>
          <ixy>0</ixy>
          <ixz>0</ixz>
          <iyy>0.421754</iyy>
          <iyz>0</iyz>
          <izz>0.0363656</izz>
        </inertia>
      </inertial>
      <collision name='upper_arm_link_collision'>
        <pose>0 0 0 0 0 0</pose>
        <geometry>
          <mesh>
            <uri>meshes/UpperArm.obj</uri>
          </mesh>
        </geometry>
      </collision>
      <visual name='upper_arm_link_visual'>
        <pose>0 0 0 0 0 0</pose>
        <geometry>
          <mesh>
            <uri>meshes/UpperArm.obj</uri>
          </mesh>
        </geometry>
      </visual>
    </link>
    <link name='shoulder_arm_gear'>
      <pose>0 0.275941 0.1273 3.14159 1.57079 3.14159</pose>
      <inertial>
        <pose>0 0 0 0 0 0</pose>
        <mass>1.778</mass>
        <inertia>
          <ixx>1</ixx>
          <ixy>0</ixy>
          <ixz>0</ixz>
          <iyy>1</iyy>
          <iyz>0</iyz>
          <izz>1</izz>
        </inertia>
      </inertial>
      <visual name='shoulder_arm_gear_visual'>
        <pose>0 0 0 0 0 0</pose>
        <geometry>
          <box>
            <size>0.025 0.025 0.025</size>
          </box>
        </geometry>
      </visual>
    </link>
<!--
    <joint name='world_arm_gear_joint' type='revolute'>
      <child>shoulder_arm_gear</child>
      <parent>world</parent>
      <axis>
        <xyz>0 0 1</xyz>
        <limit>
           <upper>0</upper>
           <lower>0</lower>
        </limit>
      </axis>
    </joint>
 -->
    <joint name='arm_gear_joint' type='revolute'>
      <parent>shoulder_arm_gear</parent>
      <child>upper_arm_link</child>
      <axis>
        <xyz>0 1 0</xyz>
        <use_parent_model_frame>1</use_parent_model_frame>
      </axis>
    </joint>
    <joint name='shoulder1_gear_joint' type='revolute'>
      <parent>shoulder_link</parent>
      <child>shoulder_arm_gear</child>
      <axis>
        <xyz>0 1 0</xyz>
        <use_parent_model_frame>1</use_parent_model_frame>
      </axis>
    </joint>
    <joint name='shoulder_lift_joint' type='gearbox'>
      <parent>shoulder_link</parent>
      <child>shoulder_arm_gear</child>
      <gearbox_ratio>1.5</gearbox_ratio>
      <gearbox_reference_body>upper_arm_link</gearbox_reference_body>
      <axis>
         <xyz>0.0 -1.0 0.0</xyz>
        <limit>
          <lower>-6.28319</lower>
          <upper>6.28319</upper>
          <effort>330</effort>
          <velocity>2.16</velocity>
        </limit>
        <use_parent_model_frame>0</use_parent_model_frame>
      </axis>
      <axis2>
         <xyz>0.0 1.0 0.0</xyz>
        <use_parent_model_frame>0</use_parent_model_frame>
      </axis2>
    </joint>
<!--
    <joint name='shoulder_lift_joint' type='revolute'>
      <child>upper_arm_link</child>
      <parent>shoulder_link</parent>
      <axis>
        <xyz>0 1 0</xyz>
        <limit>
          <lower>-6.28319</lower>
          <upper>6.28319</upper>
          <effort>330</effort>
          <velocity>2.16</velocity>
        </limit>
        <use_parent_model_frame>1</use_parent_model_frame>
      </axis>
    </joint>
-->
    <link name='forearm_link'>
      <pose>0.612 0.049041 0.1273 3.14159 1.57079 3.14159</pose>
      <inertial>
        <pose>0 0 0.28615 0 0 0</pose>
        <mass>3.87</mass>
        <inertia>
          <ixx>0.11107</ixx>
          <ixy>0</ixy>
          <ixz>0</ixz>
          <iyy>0.11107</iyy>
          <iyz>0</iyz>
          <izz>0.0108844</izz>
        </inertia>
      </inertial>
      <collision name='forearm_link_collision'>
        <pose>0 0 0 0 0 0</pose>
        <geometry>
          <mesh>
            <uri>meshes/Forearm.obj</uri>
          </mesh>
        </geometry>
      </collision>
      <visual name='forearm_link_visual'>
        <pose>0 0 0 0 0 0</pose>
        <geometry>
          <mesh>
            <uri>meshes/Forearm.obj</uri>
          </mesh>
        </geometry>
      </visual>
    </link>
    <link name='upper_forearm_gear'>
      <pose>0.612 -0.049041 0.1273 3.14159 1.57079 3.14159</pose>
      <inertial>
        <pose>0 0 0 0 0 0</pose>
        <mass>1.778</mass>
        <inertia>
          <ixx>1</ixx>
          <ixy>0</ixy>
          <ixz>0</ixz>
          <iyy>1</iyy>
          <iyz>0</iyz>
          <izz>1</izz>
        </inertia>
      </inertial>
      <visual name='upper_forearm_gear_visual'>
        <pose>0 0 0 0 0 0</pose>
        <geometry>
          <box>
            <size>0.025 0.025 0.025</size>
          </box>
        </geometry>
      </visual>
    </link>
<!--
    <joint name='world_forearm_gear_joint' type='revolute'>
      <child>upper_forearm_gear</child>
      <parent>world</parent>
      <axis>
        <xyz>0 0 1</xyz>
        <limit>
           <upper>0</upper>
           <lower>0</lower>
        </limit>
      </axis>
    </joint>
    -->
    <joint name='upperarm_gear_joint' type='revolute'>
      <parent>upper_arm_link</parent>
      <child>upper_forearm_gear</child>
      <axis>
        <xyz>0 1 0</xyz>
        <use_parent_model_frame>1</use_parent_model_frame>
      </axis>
    </joint>
    <joint name='forearm_gear_joint' type='revolute'>
      <parent>upper_forearm_gear</parent>
      <child>forearm_link</child>
      <axis>
        <xyz>0 1 0</xyz>
        <use_parent_model_frame>1</use_parent_model_frame>
      </axis>
    </joint>
    <joint name='elbow_joint' type='gearbox'>
      <parent>upper_arm_link</parent>
      <child>forearm_link</child>
      <gearbox_ratio>1.5</gearbox_ratio>
      <gearbox_reference_body>upper_forearm_gear</gearbox_reference_body>
      <axis>
         <xyz>0 -1 0</xyz>
        <limit>
          <lower>-6.28319</lower>
          <upper>6.28319</upper>
          <effort>150</effort>
          <velocity>3.15</velocity>
        </limit>
        <use_parent_model_frame>0</use_parent_model_frame>
      </axis>
      <axis2>
         <xyz>0 1 0</xyz>
        <use_parent_model_frame>0</use_parent_model_frame>
      </axis2>
    </joint>
<!--
    <joint name='elbow_joint' type='revolute'>
      <child>forearm_link</child>
      <parent>upper_arm_link</parent>
      <axis>
        <xyz>0 1 0</xyz>
        <limit>
          <lower>-6.28319</lower>
          <upper>6.28319</upper>
          <effort>150</effort>
          <velocity>3.15</velocity>
        </limit>
        <use_parent_model_frame>1</use_parent_model_frame>
      </axis>
    </joint>
-->
    <link name='wrist_1_link'>
      <pose>1.1843 0.049041 0.1273 3.14159 3.58979e-09 3.14159</pose>
      <inertial>
        <pose>0 0 0 0 0 0</pose>
        <mass>1.96</mass>
        <inertia>
          <ixx>0.00510825</ixx>
          <ixy>0</ixy>
          <ixz>0</ixz>
          <iyy>0.00510825</iyy>
          <iyz>0</iyz>
          <izz>0.0055125</izz>
        </inertia>
      </inertial>
      <collision name='wrist_1_link_collision'>
        <pose>0 0 0 0 0 0</pose>
        <geometry>
          <mesh>
            <uri>meshes/Wrist1.obj</uri>
          </mesh>
        </geometry>
      </collision>
      <visual name='wrist_1_link_visual'>
        <pose>0 0 0 0 0 0</pose>
        <geometry>
          <mesh>
            <uri>meshes/Wrist1.obj</uri>
          </mesh>
        </geometry>
      </visual>
    </link>
    <link name='forearm_w1_gear'>
      <pose>1.1843 -0.049041 0.1273 0 0 0</pose>
      <inertial>
        <pose>0 0 0 0 0 0</pose>
        <mass>1.778</mass>
        <inertia>
          <ixx>1</ixx>
          <ixy>0</ixy>
          <ixz>0</ixz>
          <iyy>1</iyy>
          <iyz>0</iyz>
          <izz>1</izz>
        </inertia>
      </inertial>
      <visual name='forearm_w1_gear_visual'>
        <pose>0 0 0 0 0 0</pose>
        <geometry>
          <box>
            <size>0.025 0.025 0.025</size>
          </box>
        </geometry>
      </visual>
    </link>
    <joint name='fore_gear_joint' type='revolute'>
      <parent>forearm_link</parent>
      <child>forearm_w1_gear</child>
      <axis>
        <xyz>0 1 0</xyz>
        <use_parent_model_frame>1</use_parent_model_frame>
      </axis>
    </joint>
    <joint name='w1_gear_joint' type='revolute'>
      <parent>forearm_w1_gear</parent>
      <child>wrist_1_link</child>
      <axis>
        <xyz>0 1 0</xyz>
        <use_parent_model_frame>1</use_parent_model_frame>
      </axis>
    </joint>
    <joint name='wrist_1_joint' type='gearbox'>
      <parent>forearm_link</parent>
      <child>forearm_w1_gear</child>
      <gearbox_ratio>-1.5</gearbox_ratio>
      <gearbox_reference_body>wrist_1_link</gearbox_reference_body>
      <axis>
         <xyz>0.0 -1.0 0.0</xyz>
        <limit>
          <lower>-6.28319</lower>
          <upper>6.28319</upper>
          <effort>54</effort>
          <velocity>3.2</velocity>
        </limit>
        <use_parent_model_frame>0</use_parent_model_frame>
      </axis>
      <axis2>
         <xyz>0.0 1.0 0.0</xyz>
        <use_parent_model_frame>0</use_parent_model_frame>
      </axis2>
    </joint>
<!--
    <joint name='wrist_forearm_w1_gear1_joint' type='revolute'>
      <child>wrist_1_link</child>
      <parent>forearm_link</parent>
      <axis>
        <xyz>0 1 0</xyz>
        <limit>
          <lower>-6.28319</lower>
          <upper>6.28319</upper>
          <effort>54</effort>
          <velocity>3.2</velocity>
        </limit>
        <use_parent_model_frame>1</use_parent_model_frame>
      </axis>
    </joint>
-->
    <link name='wrist_2_link'>
      <pose>1.1843 0.163941 0.1273 3.14159 3.58979e-09 3.14159</pose>
      <inertial>
        <pose>0 0 0 0 0 0</pose>
        <mass>1.96</mass>
        <inertia>
          <ixx>0.00510825</ixx>
          <ixy>0</ixy>
          <ixz>0</ixz>
          <iyy>0.00510825</iyy>
          <iyz>0</iyz>
          <izz>0.0055125</izz>
        </inertia>
      </inertial>
      <collision name='wrist_2_link_collision'>
        <pose>0 0 0 0 0 0</pose>
        <geometry>
          <mesh>
            <uri>meshes/Wrist2.obj</uri>
          </mesh>
        </geometry>
      </collision>
      <visual name='wrist_2_link_visual'>
        <pose>0 0 0 0 0 0</pose>
        <geometry>
          <mesh>
            <uri>meshes/Wrist2.obj</uri>
          </mesh>
        </geometry>
      </visual>
    </link>
    <link name='w1_w2_gear'>
      <pose>1.1843 0.163941 0.2073 3.14159 3.58979e-09 3.14159</pose>
      <inertial>
        <pose>0 0 0 0 0 0</pose>
        <mass>1.778</mass>
        <inertia>
          <ixx>1</ixx>
          <ixy>0</ixy>
          <ixz>0</ixz>
          <iyy>1</iyy>
          <iyz>0</iyz>
          <izz>1</izz>
        </inertia>
      </inertial>
      <visual name='w1_w2_gear_visual'>
        <pose>0 0 0 0 0 0</pose>
        <geometry>
          <box>
            <size>0.025 0.025 0.025</size>
          </box>
        </geometry>
      </visual>
    </link>
    <joint name='wrist1_gear_joint' type='revolute'>
      <parent>wrist_1_link</parent>
      <child>w1_w2_gear</child>
      <axis>
        <xyz>0 0 -1</xyz>
        <use_parent_model_frame>1</use_parent_model_frame>
      </axis>
    </joint>
    <joint name='w2_gear_joint' type='revolute'>
      <parent>w1_w2_gear</parent>
      <child>wrist_2_link</child>
      <axis>
        <xyz>0 0 -1</xyz>
        <use_parent_model_frame>1</use_parent_model_frame>
      </axis>
    </joint>
    <joint name='wrist_2_joint' type='gearbox'>
      <parent>wrist_1_link</parent>
      <child>wrist_2_link</child>
      <gearbox_ratio>1.5</gearbox_ratio>
      <gearbox_reference_body>w1_w2_gear</gearbox_reference_body>
      <axis>
         <xyz>0.0 0.0 -1.0</xyz>
        <limit>
          <lower>-6.28319</lower>
          <upper>6.28319</upper>
          <effort>54</effort>
          <velocity>3.2</velocity>
        </limit>
        <use_parent_model_frame>0</use_parent_model_frame>
      </axis>
      <axis2>
         <xyz>0.0 0.0 -1.0</xyz>
        <use_parent_model_frame>0</use_parent_model_frame>
      </axis2>
    </joint>
  <!-- 
    <joint name='wrist_2_joint' type='revolute'>
      <child>wrist_2_link</child>
      <parent>wrist_1_link</parent>
      <axis>
        <xyz>0 0 -1</xyz>
        <limit>
          <lower>-6.28319</lower>
          <upper>6.28319</upper>
          <effort>54</effort>
          <velocity>3.2</velocity>
        </limit>
        <use_parent_model_frame>1</use_parent_model_frame>
      </axis>
    </joint>
-->
    <link name='wrist_3_link'>
      <pose>1.1843 0.163941 0.0116 3.14159 3.58979e-09 3.14159</pose>
      <inertial>
        <pose>0 0 0 0 0 0</pose>
        <mass>0.202</mass>
        <inertia>
          <ixx>0.000526462</ixx>
          <ixy>0</ixy>
          <ixz>0</ixz>
          <iyy>0.000526462</iyy>
          <iyz>0</iyz>
          <izz>0.000568125</izz>
        </inertia>
      </inertial>
      <collision name='wrist_3_link_collision'>
        <pose>0 0 0 0 0 0</pose>
        <geometry>
          <mesh>
            <uri>meshes/Wrist3.obj</uri>
          </mesh>
        </geometry>
      </collision>
      <visual name='wrist_3_link_visual'>
        <pose>0 0 0 0 0 0</pose>
        <geometry>
          <mesh>
            <uri>meshes/Wrist3.obj</uri>
          </mesh>
        </geometry>
      </visual>
    </link>
    <link name='w2_w3_gear'>
      <pose>1.1843 0.083941 0.0116 0 0 0</pose>
      <inertial>
        <pose>0 0 0 0 0 0</pose>
        <mass>1.778</mass>
        <inertia>
          <ixx>1</ixx>
          <ixy>0</ixy>
          <ixz>0</ixz>
          <iyy>1</iyy>
          <iyz>0</iyz>
          <izz>1</izz>
        </inertia>
      </inertial>
      <visual name='w2_w3_gear_visual'>
        <pose>0 0 0 0 0 0</pose>
        <geometry>
          <box>
            <size>0.025 0.025 0.025</size>
          </box>
        </geometry>
      </visual>
    </link>
    <joint name='wrist2_gear_joint' type='revolute'>
      <parent>wrist_2_link</parent>
      <child>w2_w3_gear</child>
      <axis>
        <xyz>0 1 0</xyz>
        <use_parent_model_frame>1</use_parent_model_frame>
      </axis>
    </joint>
    <joint name='w3_gear_joint' type='revolute'>
      <parent>w2_w3_gear</parent>
      <child>wrist_3_link</child>
      <axis>
        <xyz>0 1 0</xyz>
        <use_parent_model_frame>1</use_parent_model_frame>
      </axis>
    </joint>
    <joint name='wrist_3_joint' type='gearbox'>
      <parent>wrist_2_link</parent>
      <child>wrist_3_link</child>
      <gearbox_ratio>1.5</gearbox_ratio>
      <gearbox_reference_body>w2_w3_gear</gearbox_reference_body>
      <axis>
         <xyz>0.0 -1.0 0.0</xyz>
        <limit>
          <lower>-6.28319</lower>
          <upper>6.28319</upper>
          <effort>54</effort>
          <velocity>3.2</velocity>
        </limit>
        <use_parent_model_frame>0</use_parent_model_frame>
      </axis>
      <axis2>
         <xyz>0.0 1.0 0.0</xyz>
        <use_parent_model_frame>0</use_parent_model_frame>
      </axis2>
    </joint>
<!--
    <joint name='wrist_3_joint' type='revolute'>
      <child>wrist_3_link</child>
      <parent>wrist_2_link</parent>
      <axis>
        <xyz>0 1 0</xyz>
        <limit>
          <lower>-6.28319</lower>
          <upper>6.28319</upper>
          <effort>54</effort>
          <velocity>3.2</velocity>
        </limit>
        <use_parent_model_frame>1</use_parent_model_frame>
      </axis>
    </joint>
-->
    <link name="hand">
      <pose>1.1843 0.256 0.0116 0 0 0</pose> 
      <self_collide>false</self_collide>
      <inertial>
        <pose>0 0.035 0 0 0 0</pose>
        <inertia>
          <ixx>0.00053312</ixx>
          <ixy>0</ixy>
          <ixz>0</ixz>
          <iyy>0.00065312</iyy>
          <iyz>0</iyz>
          <izz>0.000904</izz>
        </inertia>
        <mass>0.96</mass>
      </inertial>
      <visual name="hand_geom_visual">
        <pose>0 0.035 0 0 0 0</pose>
        <geometry>
          <mesh>
            <uri>meshes/schunk_base.obj</uri>
          </mesh>
        </geometry>
      </visual>
      <collision name="hand_geom_collision">
        <pose>0 0.035 0 0 0 0</pose>
        <geometry>
          <mesh>
            <uri>meshes/schunk_base.obj</uri>
          </mesh>
        </geometry>
      </collision>
      <collision name="hand_tab1_geom_collision">
        <pose>-0.043 0.036 0.009 0 0 0</pose>
        <geometry>
          <box>
            <size>0.006 0.012 0.012</size>
          </box>
        </geometry>
      </collision>
      <collision name="hand_tab2_geom_collision">
        <pose>-0.043 0.036 -0.009 0 0 0</pose>
        <geometry>
          <box>
            <size>0.006 0.012 0.012</size>
          </box>
        </geometry>
      </collision>
    </link>

    <joint name="fixed_hand_to_wrist" type="revolute"> 
      <parent>wrist_3_link</parent>
      <child>hand</child>
      <axis>
        <xyz>0 0 1</xyz>
        <limit>
          <lower>-.00001</lower>
          <upper>0.00001</upper>
        </limit>
      </axis>
    </joint>

    <link name="l_finger">
      <pose>1.1843 0.256 0.0116 0 0 0</pose> 
      <self_collide>false</self_collide>
      <inertial>
        <pose>-0.0205 0.0798 0 0 0 0</pose>
        <inertia>
          <ixx>0.0000095236</ixx>
          <ixy>0</ixy>
          <ixz>0</ixz>
          <iyy>0.0000072</iyy>
          <iyz>0</iyz>
          <izz>0.0000052036</izz>
        </inertia>
        <mass>0.12</mass>
      </inertial>
      <visual name="l_finger_geom_visual">
        <pose>-.0205 0.0798 0 0 0 0</pose>
        <geometry>
          <mesh>
            <uri>meshes/schunk_left_finger.obj</uri>
          </mesh>
        </geometry>
      </visual>
      <collision name="l_finger_tip_geom_collision">
        <pose>-0.0205 0.0798 0 0 0 0</pose>
        <geometry>
          <mesh>
            <uri>meshes/schunk_left_finger.obj</uri>
          </mesh>
        </geometry>
        <surface>
          <friction>
            <ode>
              <mu>100</mu>          <!-- DO NOT MODIFY -->
              <mu2>100</mu2>        <!-- DO NOT MODIFY -->
              <fdir1>0 0 0</fdir1>
              <slip1>0.0</slip1>
              <slip2>0.0</slip2>
            </ode>
            <bullet>
              <friction>100</friction>                  <!-- DO NOT MODIFY -->
              <friction2>100</friction2>                <!-- DO NOT MODIFY --> 
              <fdir1>0 0 0</fdir1>
              <rolling_friction>100</rolling_friction>  <!-- DO NOT MODIFY -->
            </bullet>
          </friction>
          <contact>
            <ode>
              <soft_cfm>0</soft_cfm>
              <soft_erp>0.2</soft_erp>
              <kp>1e12</kp>
              <kd>1.0</kd>
              <max_vel>0.01</max_vel>
              <min_depth>0.0</min_depth>
            </ode>
            <bullet>
              <soft_cfm>0</soft_cfm>
              <soft_erp>0.2</soft_erp>
              <kp>1e12</kp>
              <kd>1.0</kd>
              <split_impulse>1</split_impulse>
              <split_impulse_penetration_threshold>-0.01</split_impulse_penetration_threshold>
            </bullet>
          </contact>
        </surface>
      </collision>
    </link>
    <link name="r_finger">
      <pose>1.1843 0.256 0.0116 0 0 0</pose> 
      <self_collide>false</self_collide>
      <inertial>
        <pose>0.0205 0.0798 0 0 0 0</pose>
        <inertia>
          <ixx>0.0000095236</ixx>
          <ixy>0</ixy>
          <ixz>0</ixz>
          <iyy>0.0000072</iyy>
          <iyz>0</iyz>
          <izz>0.0000052036</izz>
        </inertia>
        <mass>0.12</mass>
      </inertial>
      <visual name="r_finger_geom_visual">
        <pose>0.0205 0.0798 0 0 0 0</pose>
        <geometry>
          <mesh>
            <uri>meshes/schunk_right_finger.obj</uri>
          </mesh>
        </geometry>
      </visual>
      <collision name="r_finger_tip_geom_collision">
        <pose>0.0205 0.0798 0 0 0 0</pose>
        <geometry>
          <mesh>
            <uri>meshes/schunk_right_finger.obj</uri>
          </mesh>
        </geometry>
        <surface>
          <friction>
            <ode>
              <mu>100</mu>          <!-- DO NOT MODIFY -->
              <mu2>100</mu2>        <!-- DO NOT MODIFY -->
              <fdir1>0 0 0</fdir1>
              <slip1>0.0</slip1>
              <slip2>0.0</slip2>
            </ode>
            <bullet>
              <friction>100</friction>                  <!-- DO NOT MODIFY -->
              <friction2>100</friction2>                <!-- DO NOT MODIFY --> 
              <fdir1>0 0 0</fdir1>
              <rolling_friction>100</rolling_friction>  <!-- DO NOT MODIFY -->
            </bullet>
          </friction>
          <contact>
            <ode>
              <soft_cfm>0</soft_cfm>
              <soft_erp>0.2</soft_erp>
              <kp>1e12</kp>
              <kd>1.0</kd>
              <max_vel>0.01</max_vel>
              <min_depth>0.0</min_depth>
            </ode>
            <bullet>
              <soft_cfm>0</soft_cfm>
              <soft_erp>0.2</soft_erp>
              <kp>1e12</kp>
              <kd>1.0</kd>
              <split_impulse>1</split_impulse>
              <split_impulse_penetration_threshold>-0.01</split_impulse_penetration_threshold>
            </bullet>
          </contact>
        </surface>
      </collision>
    </link>

    <joint name="l_finger_actuator" type="prismatic"> 
      <parent>hand</parent>
      <child>l_finger</child>
      <axis>
        <dynamics>
          <damping>0.0</damping>
          <friction>0.0</friction>
        </dynamics>
        <xyz>1 0 0</xyz>
        <limit>
          <lower>-0.00001</lower>
          <upper>0.014</upper>
        </limit>
      </axis>
    </joint>

    <joint name="r_finger_actuator" type="prismatic"> 
      <parent>hand</parent>
      <child>r_finger</child>
      <axis>
        <dynamics>
          <damping>0.0</damping>
          <friction>0.0</friction>
        </dynamics>
        <xyz>1 0 0</xyz>
        <limit>
          <lower>-0.014</lower>
          <upper>0.00001</upper>
        </limit>
      </axis>
    </joint><!--
    <plugin name='ur10_controller' filename='libur10-controller.so'/>
  -->
  </model>
</sdf>
